
[2025-05-26T03:50:39.858886] Python REPL Error:
Code:
import datetime
import pytz

# Get current UTC time
utc_now = datetime.datetime.now(pytz.UTC)
print(f"Current UTC time: {utc_now.isoformat()}")

# You can also get time in different timezones
pacific = pytz.timezone('US/Pacific')
pacific_time = datetime.datetime.now(pacific)
print(f"Current Pacific time: {pacific_time.isoformat()}")
Error:
Traceback (most recent call last):
  File "/home/ec2-user/anaconda3/envs/pytorch_p310/lib/python3.10/site-packages/strands_tools/python_repl.py", line 469, in python_repl
    user_input = get_user_input(
  File "/home/ec2-user/anaconda3/envs/pytorch_p310/lib/python3.10/site-packages/strands_tools/utils/user_input.py", line 62, in get_user_input
    result = loop.run_until_complete(get_user_input_async(prompt, default))
  File "/home/ec2-user/anaconda3/envs/pytorch_p310/lib/python3.10/asyncio/base_events.py", line 625, in run_until_complete
    self._check_running()
  File "/home/ec2-user/anaconda3/envs/pytorch_p310/lib/python3.10/asyncio/base_events.py", line 584, in _check_running
    raise RuntimeError('This event loop is already running')
RuntimeError: This event loop is already running


[2025-05-26T03:50:46.285639] Python REPL Error:
Code:
import datetime

# Get current UTC time
utc_now = datetime.datetime.now(datetime.timezone.utc)
print(f"Current UTC time: {utc_now.isoformat()}")

# Get the local time
local_time = datetime.datetime.now()
print(f"Current local time: {local_time.isoformat()}")
Error:
Traceback (most recent call last):
  File "/home/ec2-user/anaconda3/envs/pytorch_p310/lib/python3.10/site-packages/strands_tools/python_repl.py", line 469, in python_repl
    user_input = get_user_input(
  File "/home/ec2-user/anaconda3/envs/pytorch_p310/lib/python3.10/site-packages/strands_tools/utils/user_input.py", line 62, in get_user_input
    result = loop.run_until_complete(get_user_input_async(prompt, default))
  File "/home/ec2-user/anaconda3/envs/pytorch_p310/lib/python3.10/asyncio/base_events.py", line 625, in run_until_complete
    self._check_running()
  File "/home/ec2-user/anaconda3/envs/pytorch_p310/lib/python3.10/asyncio/base_events.py", line 584, in _check_running
    raise RuntimeError('This event loop is already running')
RuntimeError: This event loop is already running


[2025-05-26T03:50:50.441259] Python REPL Error:
Code:
print("The current time according to Python's datetime module:")
Error:
Traceback (most recent call last):
  File "/home/ec2-user/anaconda3/envs/pytorch_p310/lib/python3.10/site-packages/strands_tools/python_repl.py", line 469, in python_repl
    user_input = get_user_input(
  File "/home/ec2-user/anaconda3/envs/pytorch_p310/lib/python3.10/site-packages/strands_tools/utils/user_input.py", line 62, in get_user_input
    result = loop.run_until_complete(get_user_input_async(prompt, default))
  File "/home/ec2-user/anaconda3/envs/pytorch_p310/lib/python3.10/asyncio/base_events.py", line 625, in run_until_complete
    self._check_running()
  File "/home/ec2-user/anaconda3/envs/pytorch_p310/lib/python3.10/asyncio/base_events.py", line 584, in _check_running
    raise RuntimeError('This event loop is already running')
RuntimeError: This event loop is already running


[2025-05-26T03:58:10.689747] Python REPL Error:
Code:
import datetime
import pytz

# Get the current UTC time
current_utc = datetime.datetime.now(pytz.UTC)
print(f"Current UTC time: {current_utc.isoformat()}")

# Format the time to make it easier to read
formatted_time = current_utc.strftime("%Y-%m-%d %H:%M:%S %Z")
print(f"Formatted time: {formatted_time}")
Error:
Traceback (most recent call last):
  File "/home/ec2-user/anaconda3/envs/pytorch_p310/lib/python3.10/site-packages/strands_tools/python_repl.py", line 469, in python_repl
    user_input = get_user_input(
  File "/home/ec2-user/anaconda3/envs/pytorch_p310/lib/python3.10/site-packages/strands_tools/utils/user_input.py", line 62, in get_user_input
    result = loop.run_until_complete(get_user_input_async(prompt, default))
  File "/home/ec2-user/anaconda3/envs/pytorch_p310/lib/python3.10/asyncio/base_events.py", line 625, in run_until_complete
    self._check_running()
  File "/home/ec2-user/anaconda3/envs/pytorch_p310/lib/python3.10/asyncio/base_events.py", line 584, in _check_running
    raise RuntimeError('This event loop is already running')
RuntimeError: This event loop is already running


[2025-05-26T03:58:14.662969] Python REPL Error:
Code:
import datetime

# Get the current time
current_time = datetime.datetime.now()
print(f"Current time: {current_time.isoformat()}")

# Format the time to make it easier to read
formatted_time = current_time.strftime("%Y-%m-%d %H:%M:%S")
print(f"Formatted time: {formatted_time}")
Error:
Traceback (most recent call last):
  File "/home/ec2-user/anaconda3/envs/pytorch_p310/lib/python3.10/site-packages/strands_tools/python_repl.py", line 469, in python_repl
    user_input = get_user_input(
  File "/home/ec2-user/anaconda3/envs/pytorch_p310/lib/python3.10/site-packages/strands_tools/utils/user_input.py", line 62, in get_user_input
    result = loop.run_until_complete(get_user_input_async(prompt, default))
  File "/home/ec2-user/anaconda3/envs/pytorch_p310/lib/python3.10/asyncio/base_events.py", line 625, in run_until_complete
    self._check_running()
  File "/home/ec2-user/anaconda3/envs/pytorch_p310/lib/python3.10/asyncio/base_events.py", line 584, in _check_running
    raise RuntimeError('This event loop is already running')
RuntimeError: This event loop is already running


[2025-05-26T03:58:41.079906] Python REPL Error:
Code:
print("Current time verification")
Error:
Traceback (most recent call last):
  File "/home/ec2-user/anaconda3/envs/pytorch_p310/lib/python3.10/site-packages/strands_tools/python_repl.py", line 469, in python_repl
    user_input = get_user_input(
  File "/home/ec2-user/anaconda3/envs/pytorch_p310/lib/python3.10/site-packages/strands_tools/utils/user_input.py", line 62, in get_user_input
    result = loop.run_until_complete(get_user_input_async(prompt, default))
  File "/home/ec2-user/anaconda3/envs/pytorch_p310/lib/python3.10/asyncio/base_events.py", line 625, in run_until_complete
    self._check_running()
  File "/home/ec2-user/anaconda3/envs/pytorch_p310/lib/python3.10/asyncio/base_events.py", line 584, in _check_running
    raise RuntimeError('This event loop is already running')
RuntimeError: This event loop is already running

